<mujoco model="onshape">
  <compiler angle="radian"/>

  <asset>
    <mesh name="palm_lower_left" file="palm_lower_left.stl"/>
    <mesh name="mcp_joint" file="mcp_joint.stl"/>
    <mesh name="pip" file="pip.stl"/>
    <mesh name="dip" file="dip.stl"/>
    <mesh name="fingertip" file="fingertip.stl"/>
    <mesh name="thumb_pip" file="thumb_pip.stl"/>
    <mesh name="thumb_dip" file="thumb_dip.stl"/>
    <mesh name="thumb_fingertip" file="thumb_fingertip.stl"/>
  </asset>

  <worldbody>
    <body name="palm_lower">
      <inertial pos="0 0 0" quat="0.497095 0.495942 -0.509424 0.497419" mass="0.237" diaginertia="0.000529322 0.000354076 0.000260868"/>
      <joint name="floating_base_joint" type="free" limited="false" actuatorfrclimited="false"/>
      <geom pos="-0.0200952 -0.0987578 -0.0347224" quat="1 0 0 0" type="mesh" contype="0" conaffinity="0" group="1" density="0" rgba="0.2 0.2 0.2 1" mesh="palm_lower_left"/>
      <geom size="0.02 0.0675 0.0175" pos="-0.0400952 -0.0407578 -0.015" type="box" rgba="0.2 0.2 0.2 1"/>
      <body name="mcp_joint_1" pos="-0.00709525 0.0230578 -0.0187224" quat="0.5 0.5 0.5 -0.5">
        <inertial pos="0 0 0" quat="0.388585 0.626468 -0.324549 0.592628" mass="0.044" diaginertia="1.47756e-05 1.31982e-05 6.0802e-06"/>
        <joint name="finger_joint_1" pos="0 0 0" axis="0 0 -1" range="-0.314 2.23" actuatorfrcrange="-0.95 0.95"/>
        <geom pos="0.0084069 0.00776624 0.0146574" quat="1 0 0 0" type="mesh" contype="0" conaffinity="0" group="1" density="0" rgba="0.2 0.2 0.2 1" mesh="mcp_joint"/>
        <geom pos="0.0084069 0.00776624 0.0146574" quat="1 0 0 0" type="mesh" rgba="0.2 0.2 0.2 1" mesh="mcp_joint"/>
        <body name="pip_1" pos="-0.0122 0.0381 0.0145" quat="0.5 -0.5 -0.5 0.5">
          <inertial pos="0 0 0" quat="0.709913 0.704273 -0.000363156 0.00475427" mass="0.032" diaginertia="4.7981e-06 4.23406e-06 2.86184e-06"/>
          <joint name="finger_joint_0" pos="0 0 0" axis="0 0 -1" range="-1.047 1.047" actuatorfrcrange="-0.95 0.95"/>
          <geom pos="0.00964336 0.0003 0.000784034" quat="0.5 -0.5 -0.5 -0.5" type="mesh" contype="0" conaffinity="0" group="1" density="0" rgba="0.2 0.2 0.2 1" mesh="pip"/>
          <geom pos="0.00964336 0.0003 0.000784034" quat="0.5 -0.5 -0.5 -0.5" type="mesh" rgba="0.2 0.2 0.2 1" mesh="pip"/>
          <body name="dip_1" pos="0.015 0.0143 -0.013" quat="0.5 0.5 -0.5 0.5">
            <inertial pos="0 0 0" quat="-0.252689 0.659216 0.238844 0.666735" mass="0.037" diaginertia="6.68256e-06 6.24841e-06 5.02002e-06"/>
            <joint name="finger_joint_2" pos="0 0 0" axis="0 0 -1" range="-0.506 1.885" actuatorfrcrange="-0.95 0.95"/>
            <geom pos="0.0211334 -0.00843212 0.00978509" quat="0 -1 0 0" type="mesh" contype="0" conaffinity="0" group="1" density="0" rgba="0.2 0.2 0.2 1" mesh="dip"/>
            <geom pos="0.0211334 -0.00843212 0.00978509" quat="0 -1 0 0" type="mesh" rgba="0.2 0.2 0.2 1" mesh="dip"/>
            <body name="fingertip_1" pos="-4.08806e-09 -0.0361 0.0002">
              <inertial pos="0 0 0" quat="0.706755 0.706755 0.0223155 0.0223155" mass="0.016" diaginertia="3.37527e-06 2.863e-06 1.54873e-06"/>
              <joint name="finger_joint_3" pos="0 0 0" axis="0 0 -1" range="-0.366 2.042" actuatorfrcrange="-0.95 0.95"/>
              <geom pos="0.0132864 -0.00611424 0.0145" quat="0 1 0 0" type="mesh" contype="0" conaffinity="0" group="1" density="0" rgba="0.2 0.2 0.2 1" mesh="fingertip"/>
              <geom pos="0.0132864 -0.00611424 0.0145" quat="0 1 0 0" type="mesh" rgba="0.2 0.2 0.2 1" mesh="fingertip"/>
            </body>
          </body>
        </body>
      </body>
      <body name="mcp_joint_2" pos="-0.00709525 -0.0223922 -0.0187224" quat="0.5 0.5 0.5 -0.5">
        <inertial pos="0 0 0" quat="0.388585 0.626468 -0.324549 0.592628" mass="0.044" diaginertia="1.47756e-05 1.31982e-05 6.0802e-06"/>
        <joint name="finger_joint_5" pos="0 0 0" axis="0 0 -1" range="-0.314 2.23" actuatorfrcrange="-0.95 0.95"/>
        <geom pos="0.0084069 0.00776624 0.0146574" quat="1 0 0 0" type="mesh" contype="0" conaffinity="0" group="1" density="0" rgba="0.2 0.2 0.2 1" mesh="mcp_joint"/>
        <geom pos="0.0084069 0.00776624 0.0146574" quat="1 0 0 0" type="mesh" rgba="0.2 0.2 0.2 1" mesh="mcp_joint"/>
        <body name="pip_2" pos="-0.0122 0.0381 0.0145" quat="0.5 -0.5 -0.5 0.5">
          <inertial pos="0 0 0" quat="0.709913 0.704273 -0.000363156 0.00475427" mass="0.032" diaginertia="4.7981e-06 4.23406e-06 2.86184e-06"/>
          <joint name="finger_joint_4" pos="0 0 0" axis="0 0 -1" range="-1.047 1.047" actuatorfrcrange="-0.95 0.95"/>
          <geom pos="0.00964336 0.0003 0.000784034" quat="0.5 -0.5 -0.5 -0.5" type="mesh" contype="0" conaffinity="0" group="1" density="0" rgba="0.2 0.2 0.2 1" mesh="pip"/>
          <geom pos="0.00964336 0.0003 0.000784034" quat="0.5 -0.5 -0.5 -0.5" type="mesh" rgba="0.2 0.2 0.2 1" mesh="pip"/>
          <body name="dip_2" pos="0.015 0.0143 -0.013" quat="0.5 0.5 -0.5 0.5">
            <inertial pos="0 0 0" quat="-0.252689 0.659216 0.238844 0.666735" mass="0.037" diaginertia="6.68256e-06 6.24841e-06 5.02002e-06"/>
            <joint name="finger_joint_6" pos="0 0 0" axis="0 0 -1" range="-0.506 1.885" actuatorfrcrange="-0.95 0.95"/>
            <geom pos="0.0211334 -0.00843212 0.00978509" quat="0 -1 0 0" type="mesh" contype="0" conaffinity="0" group="1" density="0" rgba="0.2 0.2 0.2 1" mesh="dip"/>
            <geom pos="0.0211334 -0.00843212 0.00978509" quat="0 -1 0 0" type="mesh" rgba="0.2 0.2 0.2 1" mesh="dip"/>
            <body name="fingertip_2" pos="0 -0.0361 0.0002">
              <inertial pos="0 0 0" quat="0.706755 0.706755 0.0223155 0.0223155" mass="0.016" diaginertia="3.37527e-06 2.863e-06 1.54873e-06"/>
              <joint name="finger_joint_7" pos="0 0 0" axis="0 0 -1" range="-0.366 2.042" actuatorfrcrange="-0.95 0.95"/>
              <geom pos="0.0132864 -0.00611424 0.0145" quat="0 1 0 0" type="mesh" contype="0" conaffinity="0" group="1" density="0" rgba="0.2 0.2 0.2 1" mesh="fingertip"/>
              <geom pos="0.0132864 -0.00611424 0.0145" quat="0 1 0 0" type="mesh" rgba="0.2 0.2 0.2 1" mesh="fingertip"/>
            </body>
          </body>
        </body>
      </body>
      <body name="mcp_joint_3" pos="-0.00709525 -0.0678422 -0.0187224" quat="0.5 0.5 0.5 -0.5">
        <inertial pos="0 0 0" quat="0.388585 0.626468 -0.324549 0.592628" mass="0.044" diaginertia="1.47756e-05 1.31982e-05 6.0802e-06"/>
        <joint name="finger_joint_9" pos="0 0 0" axis="0 0 -1" range="-0.314 2.23" actuatorfrcrange="-0.95 0.95"/>
        <geom pos="0.0084069 0.00776624 0.0146574" quat="1 0 0 0" type="mesh" contype="0" conaffinity="0" group="1" density="0" rgba="0.2 0.2 0.2 1" mesh="mcp_joint"/>
        <geom pos="0.0084069 0.00776624 0.0146574" quat="1 0 0 0" type="mesh" rgba="0.2 0.2 0.2 1" mesh="mcp_joint"/>
        <body name="pip_3" pos="-0.0122 0.0381 0.0145" quat="0.5 -0.5 -0.5 0.5">
          <inertial pos="0 0 0" quat="0.709913 0.704273 -0.000363156 0.00475427" mass="0.032" diaginertia="4.7981e-06 4.23406e-06 2.86184e-06"/>
          <joint name="finger_joint_8" pos="0 0 0" axis="0 0 -1" range="-1.047 1.047" actuatorfrcrange="-0.95 0.95"/>
          <geom pos="0.00964336 0.0003 0.000784034" quat="0.5 -0.5 -0.5 -0.5" type="mesh" contype="0" conaffinity="0" group="1" density="0" rgba="0.2 0.2 0.2 1" mesh="pip"/>
          <geom pos="0.00964336 0.0003 0.000784034" quat="0.5 -0.5 -0.5 -0.5" type="mesh" rgba="0.2 0.2 0.2 1" mesh="pip"/>
          <body name="dip_3" pos="0.015 0.0143 -0.013" quat="0.5 0.5 -0.5 0.5">
            <inertial pos="0 0 0" quat="-0.252689 0.659216 0.238844 0.666735" mass="0.037" diaginertia="6.68256e-06 6.24841e-06 5.02002e-06"/>
            <joint name="finger_joint_10" pos="0 0 0" axis="0 0 -1" range="-0.506 1.885" actuatorfrcrange="-0.95 0.95"/>
            <geom pos="0.0211334 -0.00843212 0.00978509" quat="0 -1 0 0" type="mesh" contype="0" conaffinity="0" group="1" density="0" rgba="0.2 0.2 0.2 1" mesh="dip"/>
            <geom pos="0.0211334 -0.00843212 0.00978509" quat="0 -1 0 0" type="mesh" rgba="0.2 0.2 0.2 1" mesh="dip"/>
            <body name="fingertip_3" pos="0 -0.0361 0.0002">
              <inertial pos="0 0 0" quat="0.706755 0.706755 0.0223155 0.0223155" mass="0.016" diaginertia="3.37527e-06 2.863e-06 1.54873e-06"/>
              <joint name="finger_joint_11" pos="0 0 0" axis="0 0 -1" range="-0.366 2.042" actuatorfrcrange="-0.95 0.95"/>
              <geom pos="0.0132864 -0.00611424 0.0145" quat="0 1 0 0" type="mesh" contype="0" conaffinity="0" group="1" density="0" rgba="0.2 0.2 0.2 1" mesh="fingertip"/>
              <geom pos="0.0132864 -0.00611424 0.0145" quat="0 1 0 0" type="mesh" rgba="0.2 0.2 0.2 1" mesh="fingertip"/>
            </body>
          </body>
        </body>
      </body>
      <body name="mcp_joint_4" pos="-0.0693952 -0.071 -0.0216224" quat="0.499898 -0.5 0.500102 -0.5">
        <inertial pos="0 0 0" quat="0.709913 0.704273 -0.000363156 0.00475427" mass="0.032" diaginertia="4.7981e-06 4.23406e-06 2.86184e-06"/>
        <joint name="finger_joint_12" pos="0 0 0" axis="0 0 -1" range="-0.349 2.094" actuatorfrcrange="-0.95 0.95"/>
        <geom pos="-0.00535664 0.003 0.000784034" quat="0.5 -0.5 -0.5 -0.5" type="mesh" contype="0" conaffinity="0" group="1" density="0" rgba="0.2 0.2 0.2 1" mesh="pip"/>
        <geom pos="-0.00535664 0.0003 0.000784034" quat="0.5 -0.5 -0.5 -0.5" type="mesh" rgba="0.2 0.2 0.2 1" mesh="pip"/>
        <body name="pip_4" pos="0 0.0143 -0.013" quat="0.5 0.5 -0.5 0.5">
          <inertial pos="0 0 0" mass="0.003" diaginertia="5.93e-07 5.49e-07 2.24e-07"/>
          <joint name="finger_joint_13" pos="0 0 0" axis="0 0 1" range="-0.47 2.443" actuatorfrcrange="-0.95 0.95"/>
          <geom pos="0.0119619 0 -0.0158526" quat="0.707107 0.707107 0 0" type="mesh" contype="0" conaffinity="0" group="1" density="0" rgba="0.2 0.2 0.2 1" mesh="thumb_pip"/>
          <geom pos="0.0119619 0 -0.0158526" quat="0.707107 0.707107 0 0" type="mesh" rgba="0.2 0.2 0.2 1" mesh="thumb_pip"/>
          <body name="dip_4" pos="0 0.0145 -0.017" quat="0.707107 -0.707107 0 0">
            <inertial pos="0 0 0" quat="0.708624 0.704906 0.00637342 0.0303153" mass="0.038" diaginertia="8.48742e-06 7.67823e-06 3.82835e-06"/>
            <joint name="finger_joint_14" pos="0 0 0" axis="0 0 -1" range="-1.2 1.9" actuatorfrcrange="-0.95 0.95"/>
            <geom pos="0.0439687 0.057953 -0.00862868" quat="1 0 0 0" type="mesh" contype="0" conaffinity="0" group="1" density="0" rgba="0.2 0.2 0.2 1" mesh="thumb_dip"/>
            <geom pos="0.0439687 0.057953 -0.00862868" quat="1 0 0 0" type="mesh" rgba="0.2 0.2 0.2 1" mesh="thumb_dip"/>
            <body name="fingertip_4" pos="0 0.0466 0.0002" quat="0 0 0 1">
              <inertial pos="0 0 0" quat="0.704307 0.709299 0.006848 -0.0282727" mass="0.049" diaginertia="2.03882e-05 1.98443e-05 4.32049e-06"/>
              <joint name="finger_joint_15" pos="0 0 0" axis="0 0 -1" range="-1.34 1.88" actuatorfrcrange="-0.95 0.95"/>
              <geom pos="0.0625595 0.0784597 0.0489929" quat="1 0 0 0" type="mesh" contype="0" conaffinity="0" group="1" density="0" rgba="0.2 0.2 0.2 1" mesh="thumb_fingertip"/>
              <geom pos="0.0625595 0.0784597 0.0489929" quat="1 0 0 0" type="mesh" rgba="0.2 0.2 0.2 1" mesh="thumb_fingertip"/>
            </body>
          </body>
        </body>
      </body>
    </body>
  </worldbody>
</mujoco>
