<mujoco model="ur5e_rg2_l">
    <compiler angle="radian" assetdir="./mesh" autolimits="true" />

    <default>
        <joint axis="0 1 0" range="-6.28319 6.28319" armature="0.05" damping="0.05" />
        <position ctrlrange="-6.2831 6.2831" />

        <default class="visual_l">
            <geom type="mesh" contype="0" conaffinity="0" group="2" />
        </default>
        <default class="collision_l">
            <geom type="capsule" group="3" />
            <default class="eef_collision_l">
                <geom type="cylinder" />
            </default>
        </default>
        <site size="0.001" rgba="0.5 0.5 0.5 0.3" group="4" />

        <!-- Reference:
      https://www.universal-robots.com/articles/ur/robot-care-maintenance/max-joint-torques/ -->
        <default class="size3_l">
            <joint armature="0.1" damping="200" />
            <position kp="3500" forcerange="-500 500" />
            <default class="size3_limited_l">
                <joint range="-3.1415 3.1415" />
                <position ctrlrange="-3.1415 3.1415" />
            </default>
        </default>
        
        <default class="size1_l">
            <joint armature="0.1" damping="15" />
            <position kp="3000" forcerange="-28 28" />
        </default>

        <default class="size_finger_medium_l">
            <joint armature="0.1" damping="40" />
            <position kp="5" forcerange="-0.5 0.5" />
        </default>

        <default class="size_finger_light_l">
            <joint armature="0.1" damping="40" />
            <position kp="3" forcerange="-1.5 1.5" />
        </default>
    </default>

    <asset>
        <material name="black_l" specular="0.5" shininess="0.25" rgba="0.033 0.033 0.033 1" />
        <material name="jointgray_l" specular="0.5" shininess="0.25" rgba="0.278 0.278 0.278 1" />
        <material name="linkgray_l" specular="0.5" shininess="0.25" rgba="0.82 0.82 0.82 1" />
        <material name="urblue_l" specular="0.5" shininess="0.25" rgba="0.49 0.678 0.8 1" />
        <!-- UR5e mesh files -->
        <mesh name='base_0_l' file="base_0.obj" />
        <mesh name="base_1_l" file="base_1.obj" />
        <mesh name="shoulder_0_l" file="shoulder_0.obj" />
        <mesh name="shoulder_1_l" file="shoulder_1.obj" />
        <mesh name="shoulder_2_l" file="shoulder_2.obj" />
        <mesh name="upperarm_0_l" file="upperarm_0.obj" />
        <mesh name="upperarm_1_l" file="upperarm_1.obj" />
        <mesh name="upperarm_2_l" file="upperarm_2.obj" />
        <mesh name="upperarm_3_l" file="upperarm_3.obj" />
        <mesh name="forearm_0_l" file="forearm_0.obj" />
        <mesh name="forearm_1_l" file="forearm_1.obj" />
        <mesh name="forearm_2_l" file="forearm_2.obj" />
        <mesh name="forearm_3_l" file="forearm_3.obj" />
        <mesh name="wrist1_0_l" file="wrist1_0.obj" />
        <mesh name="wrist1_1_l" file="wrist1_1.obj" />
        <mesh name="wrist1_2_l" file="wrist1_2.obj" />
        <mesh name="wrist2_0_l" file="wrist2_0.obj" />
        <mesh name="wrist2_1_l" file="wrist2_1.obj" />
        <mesh name="wrist2_2_l" file="wrist2_2.obj" />
        <mesh name="wrist3_l" file="wrist3.obj" />
        <mesh name="palm_lower_l" file="palm_lower.stl"/>
        <mesh name="mcp_joint_l" file="mcp_joint.stl"/>
        <mesh name="pip_l" file="pip.stl"/>
        <mesh name="dip_l" file="dip.stl"/>
        <mesh name="fingertip_l" file="fingertip.stl"/>
        <mesh name="thumb_pip_l" file="thumb_pip.stl"/>
        <mesh name="thumb_dip_l" file="thumb_dip.stl"/>
        <mesh name="thumb_fingertip_l" file="thumb_fingertip.stl"/>
    </asset>

    <worldbody>
        <body name="ur_base_l" pos="0.18 0 0.79" quat="1 0 0 0">
            <inertial mass="4.0" pos="0 0 0" diaginertia="0.00443333156 0.00443333156 0.0072" />
            <geom mesh="base_0_l" material="black_l" class="visual_l" />
            <geom mesh="base_1_l" material="jointgray_l" class="visual_l" />
            <geom type="sphere" size="0.01" pos="0 0 0.1" rgba="1 0 0 1" />
            <body name="ur_shoulder_link_l" pos="0 0 0.163">
                <inertial mass="3.7" pos="0 0 0" diaginertia="0.0102675 0.0102675 0.00666" />
                <joint name="shoulder_pan_joint_l" class="size3_l" axis="0 0 1" />
                <geom mesh="shoulder_0_l" material="urblue_l" class="visual_l" />
                <geom mesh="shoulder_1_l" material="black_l" class="visual_l" />
                <geom mesh="shoulder_2_l" material="jointgray_l" class="visual_l" />
                <geom class="collision_l" size="0.06 0.06" pos="0 0 -0.04" />
                <body name="ur_upper_arm_link_l" pos="0 0.138 0" quat="1 0 1 0">
                    <inertial mass="8.393" pos="0 0 0.2125"
                        diaginertia="0.133886 0.133886 0.0151074" />
                    <joint name="shoulder_lift_joint_l" class="size3_l" />
                    <geom mesh="upperarm_0_l" material="linkgray_l" class="visual_l" />
                    <geom mesh="upperarm_1_l" material="black_l" class="visual_l" />
                    <geom mesh="upperarm_2_l" material="jointgray_l" class="visual_l" />
                    <geom mesh="upperarm_3_l" material="urblue_l" class="visual_l" />
                    <geom class="collision_l" pos="0 -0.04 0" quat="1 1 0 0" size="0.06 0.06" />
                    <geom class="collision_l" size="0.05 0.2" pos="0 0 0.2" />
                    <body name="ur_forearm_link_l" pos="0 -0.131 0.425">
                        <inertial mass="2.275" pos="0 0 0.196"
                            diaginertia="0.0311796 0.0311796 0.004095" />
                        <joint name="elbow_joint_l" class="size3_limited_l" />
                        <geom mesh="forearm_0_l" material="urblue_l" class="visual_l" />
                        <geom mesh="forearm_1_l" material="linkgray_l" class="visual_l" />
                        <geom mesh="forearm_2_l" material="black_l" class="visual_l" />
                        <geom mesh="forearm_3_l" material="jointgray_l" class="visual_l" />
                        <geom class="collision_l" pos="0 0.08 0" quat="1 1 0 0" size="0.055 0.06" />
                        <geom class="collision_l" size="0.038 0.19" pos="0 0 0.2" />
                        <body name="ur_wrist_1_link_l" pos="0 0 0.392" quat="1 0 1 0">
                            <inertial mass="1.219" pos="0 0.127 0"
                                diaginertia="0.0025599 0.0025599 0.0021942" />
                            <joint name="wrist_1_joint_l" class="size1_l" />
                            <geom mesh="wrist1_0_l" material="black_l" class="visual_l" />
                            <geom mesh="wrist1_1_l" material="urblue_l" class="visual_l" />
                            <geom mesh="wrist1_2_l" material="jointgray_l" class="visual_l" />
                            <geom class="collision_l" pos="0 0.05 0" quat="1 1 0 0" size="0.04 0.07" />
                            <body name="ur_wrist_2_link_l" pos="0 0.127 0">
                                <inertial mass="1.219" pos="0 0 0.1"
                                    diaginertia="0.0025599 0.0025599 0.0021942" />
                                <joint name="wrist_2_joint_l" axis="0 0 1" class="size1_l" />
                                <geom mesh="wrist2_0_l" material="black_l" class="visual_l" />
                                <geom mesh="wrist2_1_l" material="urblue_l" class="visual_l" />
                                <geom mesh="wrist2_2_l" material="jointgray_l" class="visual_l" />
                                <geom class="collision_l" size="0.04 0.06" pos="0 0 0.04" />
                                <geom class="collision_l" pos="0 0.02 0.1" quat="1 1 0 0"
                                    size="0.04 0.04" />
                                <body name="ur_wrist_3_link_l" pos="0 0 0.1">
                                    <inertial mass="0.1889" pos="0 0.0771683 0" quat="1 0 0 1"
                                        diaginertia="0.000132134 9.90863e-05 9.90863e-05" />
                                    <joint name="wrist_3_joint_l" class="size1_l" />
                                    <geom material="linkgray_l" mesh="wrist3_l" class="visual_l" />
                                    <geom class="eef_collision_l" pos="0 0.08 0" quat="1 1 0 0"
                                        size="0.04 0.02" />
                                    <site name="attachment_site_l" pos="0 0.1 0" quat="-1 1 0 0" />
                                    <body name="leap_base_l" pos="-0.037595 0.11 0.051278" quat="0.5 0.5 -0.5 0.5">
                                        <body name="leap_link_l" pos="-0.057595 -0.032742 0.011278">
                                            <geom type="box" size="0.01 0.01 0.01" rgba="0 1 0 0"/>
                                        </body>
                                        <geom pos="-0.0100952 0.0257578 -0.0347224" quat="1 0 0 0" type="mesh" rgba="0 0 0 1" mesh="palm_lower_l"/>
                                        <body name="mcp_joint_l" pos="-0.00709525 0.0230578 -0.0187224" quat="0.5 0.5 0.5 -0.5">
                                            <inertial pos="0 0 0" quat="0.388585 0.626468 -0.324549 0.592628" mass="0.044" diaginertia="1.47756e-05 1.31982e-05 6.0802e-06"/>
                                            <joint name="1_l" pos="0 0 0" axis="0 0 -1" range="-0.314 2.23" actuatorfrcrange="-0.95 0.95"/>
                                            <geom pos="0.0084069 0.00776624 0.0146574" quat="1 0 0 0" type="mesh" rgba="0 0 0 1" mesh="mcp_joint_l"/>
                                            <body name="pip_l" pos="-0.0122 0.0381 0.0145" quat="0.5 -0.5 -0.5 0.5">
                                            <inertial pos="0 0 0" quat="0.709913 0.704273 -0.000363156 0.00475427" mass="0.032" diaginertia="4.7981e-06 4.23406e-06 2.86184e-06"/>
                                            <joint name="0_l" pos="0 0 0" axis="0 0 -1" range="-1.047 1.047" actuatorfrcrange="-0.95 0.95"/>
                                            <geom pos="0.00964336 0.0003 0.000784034" quat="0.5 -0.5 -0.5 -0.5" type="mesh" rgba="0 0 0 1" mesh="pip_l"/>
                                            <body name="dip_l" pos="0.015 0.0143 -0.013" quat="0.5 0.5 -0.5 0.5">
                                                <inertial pos="0 0 0" quat="-0.252689 0.659216 0.238844 0.666735" mass="0.037" diaginertia="6.68256e-06 6.24841e-06 5.02002e-06"/>
                                                <joint name="2_l" pos="0 0 0" axis="0 0 -1" range="-0.506 1.885" actuatorfrcrange="-0.95 0.95"/>
                                                <geom pos="0.0211334 -0.00843212 0.00978509" quat="0 -1 0 0" type="mesh" rgba="0 0 0 1" mesh="dip_l"/>
                                                <body name="fingertip_l" pos="-4.08806e-09 -0.0361 0.0002">
                                                <inertial pos="0 0 0" quat="0.706755 0.706755 0.0223155 0.0223155" mass="0.016" diaginertia="3.37527e-06 2.863e-06 1.54873e-06"/>
                                                <joint name="3_l" pos="0 0 0" axis="0 0 -1" range="-0.366 2.042" actuatorfrcrange="-0.95 0.95"/>
                                                <geom pos="0.0132864 -0.00611424 0.0145" quat="0 1 0 0" type="mesh" rgba="0 0 0 1" mesh="fingertip_l"/>
                                                </body>
                                            </body>
                                            </body>
                                        </body>
                                        <body name="mcp_joint_2_l" pos="-0.00709525 -0.0223922 -0.0187224" quat="0.5 0.5 0.5 -0.5">
                                            <inertial pos="0 0 0" quat="0.388585 0.626468 -0.324549 0.592628" mass="0.044" diaginertia="1.47756e-05 1.31982e-05 6.0802e-06"/>
                                            <joint name="5_l" pos="0 0 0" axis="0 0 -1" range="-0.314 2.23" actuatorfrcrange="-0.95 0.95"/>
                                            <geom pos="0.0084069 0.00776624 0.0146574" quat="1 0 0 0" type="mesh" rgba="0 0 0 1" mesh="mcp_joint_l"/>
                                            <body name="pip_2_l" pos="-0.0122 0.0381 0.0145" quat="0.5 -0.5 -0.5 0.5">
                                            <inertial pos="0 0 0" quat="0.709913 0.704273 -0.000363156 0.00475427" mass="0.032" diaginertia="4.7981e-06 4.23406e-06 2.86184e-06"/>
                                            <joint name="4_l" pos="0 0 0" axis="0 0 -1" range="-1.047 1.047" actuatorfrcrange="-0.95 0.95"/>
                                            <geom pos="0.00964336 0.0003 0.000784034" quat="0.5 -0.5 -0.5 -0.5" type="mesh" rgba="0 0 0 1" mesh="pip_l"/>
                                            <body name="dip_2_l" pos="0.015 0.0143 -0.013" quat="0.5 0.5 -0.5 0.5">
                                                <inertial pos="0 0 0" quat="-0.252689 0.659216 0.238844 0.666735" mass="0.037" diaginertia="6.68256e-06 6.24841e-06 5.02002e-06"/>
                                                <joint name="6_l" pos="0 0 0" axis="0 0 -1" range="-0.506 1.885" actuatorfrcrange="-0.95 0.95"/>
                                                <geom pos="0.0211334 -0.00843212 0.00978509" quat="0 -1 0 0" type="mesh" rgba="0 0 0 1" mesh="dip_l"/>
                                                <body name="fingertip_2_l" pos="0 -0.0361 0.0002">
                                                <inertial pos="0 0 0" quat="0.706755 0.706755 0.0223155 0.0223155" mass="0.016" diaginertia="3.37527e-06 2.863e-06 1.54873e-06"/>
                                                <joint name="7_l" pos="0 0 0" axis="0 0 -1" range="-0.366 2.042" actuatorfrcrange="-0.95 0.95"/>
                                                <geom pos="0.0132864 -0.00611424 0.0145" quat="0 1 0 0" type="mesh" rgba="0 0 0 1" mesh="fingertip_l"/>
                                                </body>
                                            </body>
                                            </body>
                                        </body>
                                        <body name="mcp_joint_3_l" pos="-0.00709525 -0.0678422 -0.0187224" quat="0.5 0.5 0.5 -0.5">
                                            <inertial pos="0 0 0" quat="0.388585 0.626468 -0.324549 0.592628" mass="0.044" diaginertia="1.47756e-05 1.31982e-05 6.0802e-06"/>
                                            <joint name="9_l" pos="0 0 0" axis="0 0 -1" range="-0.314 2.23" actuatorfrcrange="-0.95 0.95"/>
                                            <geom pos="0.0084069 0.00776624 0.0146574" quat="1 0 0 0" type="mesh" rgba="0 0 00 1" mesh="mcp_joint_l"/>
                                            <body name="pip_3_l" pos="-0.0122 0.0381 0.0145" quat="0.5 -0.5 -0.5 0.5">
                                            <inertial pos="0 0 0" quat="0.709913 0.704273 -0.000363156 0.00475427" mass="0.032" diaginertia="4.7981e-06 4.23406e-06 2.86184e-06"/>
                                            <joint name="8_l" pos="0 0 0" axis="0 0 -1" range="-1.047 1.047" actuatorfrcrange="-0.95 0.95"/>
                                            <geom pos="0.00964336 0.0003 0.000784034" quat="0.5 -0.5 -0.5 -0.5" type="mesh" rgba="0 0 0 1" mesh="pip_l"/>
                                            <body name="dip_3_l" pos="0.015 0.0143 -0.013" quat="0.5 0.5 -0.5 0.5">
                                                <inertial pos="0 0 0" quat="-0.252689 0.659216 0.238844 0.666735" mass="0.037" diaginertia="6.68256e-06 6.24841e-06 5.02002e-06"/>
                                                <joint name="10_l" pos="0 0 0" axis="0 0 -1" range="-0.506 1.885" actuatorfrcrange="-0.95 0.95"/>
                                                <geom pos="0.0211334 -0.00843212 0.00978509" quat="0 -1 0 0" type="mesh" rgba="0 0 0 1" mesh="dip_l"/>
                                                <body name="fingertip_3_l" pos="0 -0.0361 0.0002">
                                                <inertial pos="0 0 0" quat="0.706755 0.706755 0.0223155 0.0223155" mass="0.016" diaginertia="3.37527e-06 2.863e-06 1.54873e-06"/>
                                                <joint name="11_l" pos="0 0 0" axis="0 0 -1" range="-0.366 2.042" actuatorfrcrange="-0.95 0.95"/>
                                                <geom pos="0.0132864 -0.00611424 0.0145" quat="0 1 0 0" type="mesh" rgba="0 0 0 1" mesh="fingertip_l"/>
                                                </body>
                                            </body>
                                            </body>
                                        </body>
                                        <body name="pip_4_l" pos="-0.0693952 -0.00124224 -0.0216224" quat="0.707107 0 0.707107 0">
                                            <inertial pos="0 0 0" quat="0.709913 0.704273 -0.000363156 0.00475427" mass="0.032" diaginertia="4.7981e-06 4.23406e-06 2.86184e-06"/>
                                            <joint name="12_l" pos="0 0 0" axis="0 0 -1" range="-0.349 2.094" actuatorfrcrange="-0.95 0.95"/>
                                            <geom pos="-0.00535664 0.0003 0.000784034" quat="0.5 -0.5 -0.5 -0.5" type="mesh" rgba="0 0 0 1" mesh="pip_l"/>
                                            <body name="thumb_pip_l" pos="0 0.0143 -0.013" quat="0.5 0.5 -0.5 0.5">
                                            <inertial pos="0 0 0" mass="0.003" diaginertia="5.93e-07 5.49e-07 2.24e-07"/>
                                            <joint name="13_l" pos="0 0 0" axis="0 0 -1" range="-0.47 2.443" actuatorfrcrange="-0.95 0.95"/>
                                            <geom pos="0.0119619 0 -0.0158526" quat="0.707107 0.707107 0 0" type="mesh" rgba="0 0 0 1" mesh="thumb_pip_l"/>
                                            <body name="thumb_dip_l" pos="0 0.0145 -0.017" quat="0.707107 -0.707107 0 0">
                                                <inertial pos="0 0 0" quat="0.708624 0.704906 0.00637342 0.0303153" mass="0.038" diaginertia="8.48742e-06 7.67823e-06 3.82835e-06"/>
                                                <joint name="14_l" pos="0 0 0" axis="0 0 -1" range="-1.2 1.9" actuatorfrcrange="-0.95 0.95"/>
                                                <geom pos="0.0439687 0.057953 -0.00862868" quat="1 0 0 0" type="mesh" rgba="0 0 0 1" mesh="thumb_dip_l"/>
                                                <body name="thumb_fingertip_l" pos="0 0.0466 0.0002" quat="0 0 0 1">
                                                <inertial pos="0 0 0" quat="0.704307 0.709299 0.006848 -0.0282727" mass="0.049" diaginertia="2.03882e-05 1.98443e-05 4.32049e-06"/>
                                                <joint name="15_l" pos="0 0 0" axis="0 0 -1" range="-1.34 1.88" actuatorfrcrange="-0.95 0.95"/>
                                                <geom pos="0.0625595 0.0784597 0.0489929" quat="1 0 0 0" type="mesh" rgba="0 0 0 1" mesh="thumb_fingertip_l"/>
                                                </body>
                                            </body>
                                            </body>
                                        </body>
                                        </body>
                                    
                                </body>
                            </body>
                        </body>
                    </body>
                </body>
            </body>
        </body>
    </worldbody>


    <actuator>
        <position class="size3_l" name="shoulder_pan_l" joint="shoulder_pan_joint_l" />
        <position class="size3_l" name="shoulder_lift_l" joint="shoulder_lift_joint_l" />
        <position class="size3_limited_l" name="elbow_l" joint="elbow_joint_l" />
        <position class="size1_l" name="wrist_1_l" joint="wrist_1_joint_l" />
        <position class="size1_l" name="wrist_2_l" joint="wrist_2_joint_l" />
        <position class="size1_l" name="wrist_3_l" joint="wrist_3_joint_l" />

        <position class="size_finger_medium_l" name="thumb_mcp_l" joint="12_l" />
        <position class="size_finger_medium_l" name="thumb_pip_l" joint="13_l" />
        <position class="size_finger_medium_l" name="thumb_dip_l" joint="14_l" />
        <position class="size_finger_light_l" name="thumb_tip_l" joint="15_l" />

        <!-- 食指、中指、无名指关节 -->
        <position class="size_finger_medium_l" name="index_mcp_l" joint="1_l" />
        <position class="size_finger_medium_l" name="index_pip_l" joint="0_l" />
        <position class="size_finger_medium_l" name="index_dip_l" joint="2_l" />
        <position class="size_finger_light_l" name="index_tip_l" joint="3_l" />

        <position class="size_finger_medium_l" name="middle_mcp_l" joint="5_l" />
        <position class="size_finger_medium_l" name="middle_pip_l" joint="4_l" />
        <position class="size_finger_medium_l" name="middle_dip_l" joint="6_l" />
        <position class="size_finger_light_l" name="middle_tip_l" joint="7_l" />

        <position class="size_finger_medium_l" name="ring_mcp_l" joint="9_l" />
        <position class="size_finger_medium_l" name="ring_pip_l" joint="8_l" />
        <position class="size_finger_medium_l" name="ring_dip_l" joint="10_l" />
        <position class="size_finger_light_l" name="ring_tip_l" joint="11_l" />
    </actuator>


    <!-- # of actuator is 7 -->
    <!-- <keyframe>
    <key name="home" qpos="0 0 0 -1.57079 0 1.57079 -0.7853 0.04 0.04"
        ctrl="0 0 0 -1.57079 0 1.57079 -0.7853 255"/>
  </keyframe> -->

</mujoco>