<mujoco model="ur5e_rg2">
    <compiler angle="radian" assetdir="./mesh" autolimits="true" />

    <default>
        <joint axis="0 1 0" range="-6.28319 6.28319" armature="0.05" damping="0.05" />
        <position ctrlrange="-6.2831 6.2831" />

        <default class="visual">
            <geom type="mesh" contype="0" conaffinity="0" group="2" />
        </default>
        <default class="collision">
            <geom type="capsule" group="3" />
            <default class="eef_collision">
                <geom type="cylinder" />
            </default>
        </default>
        <site size="0.001" rgba="0.5 0.5 0.5 0.3" group="4" />

        <!-- Reference:
      https://www.universal-robots.com/articles/ur/robot-care-maintenance/max-joint-torques/ -->
        <default class="size3">
            <joint armature="0.1" damping="200" />
            <position kp="3500" forcerange="-500 500" />
            <default class="size3_limited">
                <joint range="-3.1415 3.1415" />
                <position ctrlrange="-3.1415 3.1415" />
            </default>
        </default>
        
        <default class="size1">
            <joint armature="0.1" damping="15" />
            <position kp="3000" forcerange="-28 28" />
        </default>

        <default class="size_finger_medium">
            <joint armature="0.1" damping="40" />
            <position kp="5" forcerange="-0.5 0.5" />
        </default>

        <default class="size_finger_light">
            <joint armature="0.1" damping="40" />
            <position kp="3" forcerange="-1.5 1.5" />
        </default>
    </default>

    <asset>
        <material name="black" specular="0.5" shininess="0.25" rgba="0.033 0.033 0.033 1" />
        <material name="jointgray" specular="0.5" shininess="0.25" rgba="0.278 0.278 0.278 1" />
        <material name="linkgray" specular="0.5" shininess="0.25" rgba="0.82 0.82 0.82 1" />
        <material name="urblue" specular="0.5" shininess="0.25" rgba="0.49 0.678 0.8 1" />
        <!-- UR5e mesh files -->
        <mesh file="base_0.obj" />
        <mesh file="base_1.obj" />
        <mesh file="shoulder_0.obj" />
        <mesh file="shoulder_1.obj" />
        <mesh file="shoulder_2.obj" />
        <mesh file="upperarm_0.obj" />
        <mesh file="upperarm_1.obj" />
        <mesh file="upperarm_2.obj" />
        <mesh file="upperarm_3.obj" />
        <mesh file="forearm_0.obj" />
        <mesh file="forearm_1.obj" />
        <mesh file="forearm_2.obj" />
        <mesh file="forearm_3.obj" />
        <mesh file="wrist1_0.obj" />
        <mesh file="wrist1_1.obj" />
        <mesh file="wrist1_2.obj" />
        <mesh file="wrist2_0.obj" />
        <mesh file="wrist2_1.obj" />
        <mesh file="wrist2_2.obj" />
        <mesh file="wrist3.obj" />
        <mesh name="palm_lower" file="palm_lower.stl"/>
        <mesh name="mcp_joint" file="mcp_joint.stl"/>
        <mesh name="pip" file="pip.stl"/>
        <mesh name="dip" file="dip.stl"/>
        <mesh name="fingertip" file="fingertip.stl"/>
        <mesh name="thumb_pip" file="thumb_pip.stl"/>
        <mesh name="thumb_dip" file="thumb_dip.stl"/>
        <mesh name="thumb_fingertip" file="thumb_fingertip.stl"/>
    </asset>

    <worldbody>
        <body name="ur_base" pos="0.18 0 0.79" quat="1 0 0 0">
            <inertial mass="4.0" pos="0 0 0" diaginertia="0.00443333156 0.00443333156 0.0072" />
            <geom mesh="base_0" material="black" class="visual" />
            <geom mesh="base_1" material="jointgray" class="visual" />
            <geom type="sphere" size="0.01" pos="0 0 0.1" rgba="1 0 0 1" />
            <body name="ur_shoulder_link" pos="0 0 0.163">
                <inertial mass="3.7" pos="0 0 0" diaginertia="0.0102675 0.0102675 0.00666" />
                <joint name="shoulder_pan_joint" class="size3" axis="0 0 1" />
                <geom mesh="shoulder_0" material="urblue" class="visual" />
                <geom mesh="shoulder_1" material="black" class="visual" />
                <geom mesh="shoulder_2" material="jointgray" class="visual" />
                <geom class="collision" size="0.06 0.06" pos="0 0 -0.04" />
                <body name="ur_upper_arm_link" pos="0 0.138 0" quat="1 0 1 0">
                    <inertial mass="8.393" pos="0 0 0.2125"
                        diaginertia="0.133886 0.133886 0.0151074" />
                    <joint name="shoulder_lift_joint" class="size3" />
                    <geom mesh="upperarm_0" material="linkgray" class="visual" />
                    <geom mesh="upperarm_1" material="black" class="visual" />
                    <geom mesh="upperarm_2" material="jointgray" class="visual" />
                    <geom mesh="upperarm_3" material="urblue" class="visual" />
                    <geom class="collision" pos="0 -0.04 0" quat="1 1 0 0" size="0.06 0.06" />
                    <geom class="collision" size="0.05 0.2" pos="0 0 0.2" />
                    <body name="ur_forearm_link" pos="0 -0.131 0.425">
                        <inertial mass="2.275" pos="0 0 0.196"
                            diaginertia="0.0311796 0.0311796 0.004095" />
                        <joint name="elbow_joint" class="size3_limited" />
                        <geom mesh="forearm_0" material="urblue" class="visual" />
                        <geom mesh="forearm_1" material="linkgray" class="visual" />
                        <geom mesh="forearm_2" material="black" class="visual" />
                        <geom mesh="forearm_3" material="jointgray" class="visual" />
                        <geom class="collision" pos="0 0.08 0" quat="1 1 0 0" size="0.055 0.06" />
                        <geom class="collision" size="0.038 0.19" pos="0 0 0.2" />
                        <body name="ur_wrist_1_link" pos="0 0 0.392" quat="1 0 1 0">
                            <inertial mass="1.219" pos="0 0.127 0"
                                diaginertia="0.0025599 0.0025599 0.0021942" />
                            <joint name="wrist_1_joint" class="size1" />
                            <geom mesh="wrist1_0" material="black" class="visual" />
                            <geom mesh="wrist1_1" material="urblue" class="visual" />
                            <geom mesh="wrist1_2" material="jointgray" class="visual" />
                            <geom class="collision" pos="0 0.05 0" quat="1 1 0 0" size="0.04 0.07" />
                            <body name="ur_wrist_2_link" pos="0 0.127 0">
                                <inertial mass="1.219" pos="0 0 0.1"
                                    diaginertia="0.0025599 0.0025599 0.0021942" />
                                <joint name="wrist_2_joint" axis="0 0 1" class="size1" />
                                <geom mesh="wrist2_0" material="black" class="visual" />
                                <geom mesh="wrist2_1" material="urblue" class="visual" />
                                <geom mesh="wrist2_2" material="jointgray" class="visual" />
                                <geom class="collision" size="0.04 0.06" pos="0 0 0.04" />
                                <geom class="collision" pos="0 0.02 0.1" quat="1 1 0 0"
                                    size="0.04 0.04" />
                                <body name="ur_wrist_3_link" pos="0 0 0.1">
                                    <inertial mass="0.1889" pos="0 0.0771683 0" quat="1 0 0 1"
                                        diaginertia="0.000132134 9.90863e-05 9.90863e-05" />
                                    <joint name="wrist_3_joint" class="size1" />
                                    <geom material="linkgray" mesh="wrist3" class="visual" />
                                    <geom class="eef_collision" pos="0 0.08 0" quat="1 1 0 0"
                                        size="0.04 0.02" />
                                    <site name="attachment_site" pos="0 0.1 0" quat="-1 1 0 0" />



                                    <body name="leap_base" pos="-0.037595 0.11 0.051278" quat="0.5 0.5 -0.5 0.5">
                                        <body name="leap_link" pos="-0.057595 -0.032742 0.011278">
                                            <geom type="box" size="0.01 0.01 0.01" rgba="0 1 0 0"/>
                                        </body>
                                        <geom pos="-0.0100952 0.0257578 -0.0347224" quat="1 0 0 0" type="mesh" rgba="0 0 0 1" mesh="palm_lower"/>
                                        <body name="mcp_joint" pos="-0.00709525 0.0230578 -0.0187224" quat="0.5 0.5 0.5 -0.5">
                                            <inertial pos="0 0 0" quat="0.388585 0.626468 -0.324549 0.592628" mass="0.044" diaginertia="1.47756e-05 1.31982e-05 6.0802e-06"/>
                                            <joint name="1" pos="0 0 0" axis="0 0 -1" range="-0.314 2.23" actuatorfrcrange="-0.95 0.95"/>
                                            <geom pos="0.0084069 0.00776624 0.0146574" quat="1 0 0 0" type="mesh" rgba="0 0 0 1" mesh="mcp_joint"/>
                                            <body name="pip" pos="-0.0122 0.0381 0.0145" quat="0.5 -0.5 -0.5 0.5">
                                            <inertial pos="0 0 0" quat="0.709913 0.704273 -0.000363156 0.00475427" mass="0.032" diaginertia="4.7981e-06 4.23406e-06 2.86184e-06"/>
                                            <joint name="0" pos="0 0 0" axis="0 0 -1" range="-1.047 1.047" actuatorfrcrange="-0.95 0.95"/>
                                            <geom pos="0.00964336 0.0003 0.000784034" quat="0.5 -0.5 -0.5 -0.5" type="mesh" rgba="0 0 0 1" mesh="pip"/>
                                            <body name="dip" pos="0.015 0.0143 -0.013" quat="0.5 0.5 -0.5 0.5">
                                                <inertial pos="0 0 0" quat="-0.252689 0.659216 0.238844 0.666735" mass="0.037" diaginertia="6.68256e-06 6.24841e-06 5.02002e-06"/>
                                                <joint name="2" pos="0 0 0" axis="0 0 -1" range="-0.506 1.885" actuatorfrcrange="-0.95 0.95"/>
                                                <geom pos="0.0211334 -0.00843212 0.00978509" quat="0 -1 0 0" type="mesh" rgba="0 0 0 1" mesh="dip"/>
                                                <body name="fingertip" pos="-4.08806e-09 -0.0361 0.0002">
                                                <inertial pos="0 0 0" quat="0.706755 0.706755 0.0223155 0.0223155" mass="0.016" diaginertia="3.37527e-06 2.863e-06 1.54873e-06"/>
                                                <joint name="3" pos="0 0 0" axis="0 0 -1" range="-0.366 2.042" actuatorfrcrange="-0.95 0.95"/>
                                                <geom pos="0.0132864 -0.00611424 0.0145" quat="0 1 0 0" type="mesh" rgba="0 0 0 1" mesh="fingertip"/>
                                                </body>
                                            </body>
                                            </body>
                                        </body>
                                        <body name="mcp_joint_2" pos="-0.00709525 -0.0223922 -0.0187224" quat="0.5 0.5 0.5 -0.5">
                                            <inertial pos="0 0 0" quat="0.388585 0.626468 -0.324549 0.592628" mass="0.044" diaginertia="1.47756e-05 1.31982e-05 6.0802e-06"/>
                                            <joint name="5" pos="0 0 0" axis="0 0 -1" range="-0.314 2.23" actuatorfrcrange="-0.95 0.95"/>
                                            <geom pos="0.0084069 0.00776624 0.0146574" quat="1 0 0 0" type="mesh" rgba="0 0 0 1" mesh="mcp_joint"/>
                                            <body name="pip_2" pos="-0.0122 0.0381 0.0145" quat="0.5 -0.5 -0.5 0.5">
                                            <inertial pos="0 0 0" quat="0.709913 0.704273 -0.000363156 0.00475427" mass="0.032" diaginertia="4.7981e-06 4.23406e-06 2.86184e-06"/>
                                            <joint name="4" pos="0 0 0" axis="0 0 -1" range="-1.047 1.047" actuatorfrcrange="-0.95 0.95"/>
                                            <geom pos="0.00964336 0.0003 0.000784034" quat="0.5 -0.5 -0.5 -0.5" type="mesh" rgba="0 0 0 1" mesh="pip"/>
                                            <body name="dip_2" pos="0.015 0.0143 -0.013" quat="0.5 0.5 -0.5 0.5">
                                                <inertial pos="0 0 0" quat="-0.252689 0.659216 0.238844 0.666735" mass="0.037" diaginertia="6.68256e-06 6.24841e-06 5.02002e-06"/>
                                                <joint name="6" pos="0 0 0" axis="0 0 -1" range="-0.506 1.885" actuatorfrcrange="-0.95 0.95"/>
                                                <geom pos="0.0211334 -0.00843212 0.00978509" quat="0 -1 0 0" type="mesh" rgba="0 0 0 1" mesh="dip"/>
                                                <body name="fingertip_2" pos="0 -0.0361 0.0002">
                                                <inertial pos="0 0 0" quat="0.706755 0.706755 0.0223155 0.0223155" mass="0.016" diaginertia="3.37527e-06 2.863e-06 1.54873e-06"/>
                                                <joint name="7" pos="0 0 0" axis="0 0 -1" range="-0.366 2.042" actuatorfrcrange="-0.95 0.95"/>
                                                <geom pos="0.0132864 -0.00611424 0.0145" quat="0 1 0 0" type="mesh" rgba="0 0 0 1" mesh="fingertip"/>
                                                </body>
                                            </body>
                                            </body>
                                        </body>
                                        <body name="mcp_joint_3" pos="-0.00709525 -0.0678422 -0.0187224" quat="0.5 0.5 0.5 -0.5">
                                            <inertial pos="0 0 0" quat="0.388585 0.626468 -0.324549 0.592628" mass="0.044" diaginertia="1.47756e-05 1.31982e-05 6.0802e-06"/>
                                            <joint name="9" pos="0 0 0" axis="0 0 -1" range="-0.314 2.23" actuatorfrcrange="-0.95 0.95"/>
                                            <geom pos="0.0084069 0.00776624 0.0146574" quat="1 0 0 0" type="mesh" rgba="0 0 00 1" mesh="mcp_joint"/>
                                            <body name="pip_3" pos="-0.0122 0.0381 0.0145" quat="0.5 -0.5 -0.5 0.5">
                                            <inertial pos="0 0 0" quat="0.709913 0.704273 -0.000363156 0.00475427" mass="0.032" diaginertia="4.7981e-06 4.23406e-06 2.86184e-06"/>
                                            <joint name="8" pos="0 0 0" axis="0 0 -1" range="-1.047 1.047" actuatorfrcrange="-0.95 0.95"/>
                                            <geom pos="0.00964336 0.0003 0.000784034" quat="0.5 -0.5 -0.5 -0.5" type="mesh" rgba="0 0 0 1" mesh="pip"/>
                                            <body name="dip_3" pos="0.015 0.0143 -0.013" quat="0.5 0.5 -0.5 0.5">
                                                <inertial pos="0 0 0" quat="-0.252689 0.659216 0.238844 0.666735" mass="0.037" diaginertia="6.68256e-06 6.24841e-06 5.02002e-06"/>
                                                <joint name="10" pos="0 0 0" axis="0 0 -1" range="-0.506 1.885" actuatorfrcrange="-0.95 0.95"/>
                                                <geom pos="0.0211334 -0.00843212 0.00978509" quat="0 -1 0 0" type="mesh" rgba="0 0 0 1" mesh="dip"/>
                                                <body name="fingertip_3" pos="0 -0.0361 0.0002">
                                                <inertial pos="0 0 0" quat="0.706755 0.706755 0.0223155 0.0223155" mass="0.016" diaginertia="3.37527e-06 2.863e-06 1.54873e-06"/>
                                                <joint name="11" pos="0 0 0" axis="0 0 -1" range="-0.366 2.042" actuatorfrcrange="-0.95 0.95"/>
                                                <geom pos="0.0132864 -0.00611424 0.0145" quat="0 1 0 0" type="mesh" rgba="0 0 0 1" mesh="fingertip"/>
                                                </body>
                                            </body>
                                            </body>
                                        </body>
                                        <body name="pip_4" pos="-0.0693952 -0.00124224 -0.0216224" quat="0.707107 0 0.707107 0">
                                            <inertial pos="0 0 0" quat="0.709913 0.704273 -0.000363156 0.00475427" mass="0.032" diaginertia="4.7981e-06 4.23406e-06 2.86184e-06"/>
                                            <joint name="12" pos="0 0 0" axis="0 0 -1" range="-0.349 2.094" actuatorfrcrange="-0.95 0.95"/>
                                            <geom pos="-0.00535664 0.0003 0.000784034" quat="0.5 -0.5 -0.5 -0.5" type="mesh" rgba="0 0 0 1" mesh="pip"/>
                                            <body name="thumb_pip" pos="0 0.0143 -0.013" quat="0.5 0.5 -0.5 0.5">
                                            <inertial pos="0 0 0" mass="0.003" diaginertia="5.93e-07 5.49e-07 2.24e-07"/>
                                            <joint name="13" pos="0 0 0" axis="0 0 -1" range="-0.47 2.443" actuatorfrcrange="-0.95 0.95"/>
                                            <geom pos="0.0119619 0 -0.0158526" quat="0.707107 0.707107 0 0" type="mesh" rgba="0 0 0 1" mesh="thumb_pip"/>
                                            <body name="thumb_dip" pos="0 0.0145 -0.017" quat="0.707107 -0.707107 0 0">
                                                <inertial pos="0 0 0" quat="0.708624 0.704906 0.00637342 0.0303153" mass="0.038" diaginertia="8.48742e-06 7.67823e-06 3.82835e-06"/>
                                                <joint name="14" pos="0 0 0" axis="0 0 -1" range="-1.2 1.9" actuatorfrcrange="-0.95 0.95"/>
                                                <geom pos="0.0439687 0.057953 -0.00862868" quat="1 0 0 0" type="mesh" rgba="0 0 0 1" mesh="thumb_dip"/>
                                                <body name="thumb_fingertip" pos="0 0.0466 0.0002" quat="0 0 0 1">
                                                <inertial pos="0 0 0" quat="0.704307 0.709299 0.006848 -0.0282727" mass="0.049" diaginertia="2.03882e-05 1.98443e-05 4.32049e-06"/>
                                                <joint name="15" pos="0 0 0" axis="0 0 -1" range="-1.34 1.88" actuatorfrcrange="-0.95 0.95"/>
                                                <geom pos="0.0625595 0.0784597 0.0489929" quat="1 0 0 0" type="mesh" rgba="0 0 0 1" mesh="thumb_fingertip"/>
                                                </body>
                                            </body>
                                            </body>
                                        </body>
                                        </body>

                                    
                                </body>
                            </body>
                        </body>
                    </body>
                </body>
            </body>
        </body>
    </worldbody>


    <actuator>
        <position class="size3" name="shoulder_pan" joint="shoulder_pan_joint" />
        <position class="size3" name="shoulder_lift" joint="shoulder_lift_joint" />
        <position class="size3_limited" name="elbow" joint="elbow_joint" />
        <position class="size1" name="wrist_1" joint="wrist_1_joint" />
        <position class="size1" name="wrist_2" joint="wrist_2_joint" />
        <position class="size1" name="wrist_3" joint="wrist_3_joint" />

        <position class="size_finger_medium" name="thumb_mcp" joint="12" />
        <position class="size_finger_medium" name="thumb_pip" joint="13" />
        <position class="size_finger_medium" name="thumb_dip" joint="14" />
        <position class="size_finger_light" name="thumb_tip" joint="15" />

        <!-- 食指、中指、无名指关节 -->
        <position class="size_finger_medium" name="index_mcp" joint="1" />
        <position class="size_finger_medium" name="index_pip" joint="0" />
        <position class="size_finger_medium" name="index_dip" joint="2" />
        <position class="size_finger_light" name="index_tip" joint="3" />

        <position class="size_finger_medium" name="middle_mcp" joint="5" />
        <position class="size_finger_medium" name="middle_pip" joint="4" />
        <position class="size_finger_medium" name="middle_dip" joint="6" />
        <position class="size_finger_light" name="middle_tip" joint="7" />

        <position class="size_finger_medium" name="ring_mcp" joint="9" />
        <position class="size_finger_medium" name="ring_pip" joint="8" />
        <position class="size_finger_medium" name="ring_dip" joint="10" />
        <position class="size_finger_light" name="ring_tip" joint="11" />
    </actuator>


    <!-- # of actuator is 7 -->
    <!-- <keyframe>
    <key name="home" qpos="0 0 0 -1.57079 0 1.57079 -0.7853 0.04 0.04"
        ctrl="0 0 0 -1.57079 0 1.57079 -0.7853 255"/>
  </keyframe> -->

</mujoco>